<?xml version="1.0" ?>
<!-- =================================================================================== -->
<!-- |    This document was autogenerated by xacro from nero_with_grinder.xacro        | -->
<!-- |    EDITING THIS FILE BY HAND IS NOT RECOMMENDED                                 | -->
<!-- =================================================================================== -->
<robot name="nero_with_grinder">
  <!--
        nero_with_grinder.xacro
        =======================
        Nero arm with grinder and camera attached to flange.
        Base: 叶片车模拟_blender.stl

        Structure:
          workbench_link (root, 叶片车) -> base_link (nero) -> link1 -> ... -> link7 -> gripper_flange -> grinder

        Usage:
        xacro nero_with_grinder.xacro
    -->

  <!-- 叶片车 workbench link (ROOT) -->
  <link name="workbench_link">
    <inertial>
      <origin xyz="0 0 0.1" rpy="0 0 0"/>
      <mass value="10.0"/>
      <inertia ixx="0.5" ixy="0" ixz="0" iyy="0.5" iyz="0" izz="0.5"/>
    </inertial>
    <visual>
      <origin xyz="0 0 0" rpy="0 0 0"/>
      <geometry>
        <mesh filename="package://my_robot_description/meshes/workcells/blade_polishing/叶片车模拟_blender.STL"/>
      </geometry>
      <material name="grey">
        <color rgba="0.5 0.5 0.5 1.0"/>
      </material>
    </visual>
    <collision>
      <origin xyz="0 0 0.1" rpy="0 0 0"/>
      <geometry>
        <box size="0.5 0.5 0.2"/>
      </geometry>
    </collision>
  </link>


  <!-- Joint from workbench_link to nero base_link (with offset) -->
  <joint name="workbench_to_base_link_joint" type="fixed">
    <origin xyz="-0.0564 -0.37 0.1241" rpy="0 0 -1.571"/>
    <parent link="workbench_link"/>
    <child link="base_link"/>
  </joint>
  <link name="base_link">
    <inertial>
      <origin rpy="0 0 0" xyz="-0.00319465997 -0.00005467608 0.04321758463"/>
      <mass value="1.06458435"/>
      <inertia ixx="0.00102659855152" ixy="0.00000186219753" ixz="-0.00000295298037" iyy="0.00114399299508" iyz="-0.00000078763492" izz="0.00090872933022"/>
    </inertial>
    <visual>
      <origin rpy="0 0 0" xyz="0 0 0"/>
      <geometry>
        <mesh filename="package://my_robot_description/meshes/robots/nero/base_link.stl"/>
      </geometry>
    </visual>
    <collision>
      <origin rpy="0 0 0" xyz="0 0 0"/>
      <geometry>
        <mesh filename="package://my_robot_description/meshes/robots/nero/base_link.stl"/>
      </geometry>
    </collision>
  </link>
  <link name="link1">
    <inertial>
      <origin rpy="0 0 0" xyz="-0.00076810578 -0.00005718031 -0.00686372765"/>
      <mass value="0.76710504"/>
      <inertia ixx="0.00066689512233" ixy="0.00000273938306" ixz="0.00001463284987" iyy="0.00054501235592" iyz="0.00000183168344" izz="0.00051509465737"/>
    </inertial>
    <visual>
      <origin rpy="0 0 0" xyz="0 0 0"/>
      <geometry>
        <mesh filename="package://my_robot_description/meshes/robots/nero/link1.stl"/>
      </geometry>
    </visual>
    <collision>
      <origin rpy="0 0 0" xyz="0 0 0"/>
      <geometry>
        <mesh filename="package://my_robot_description/meshes/robots/nero/link1.stl"/>
      </geometry>
    </collision>
  </link>
  <joint name="joint1" type="revolute">
    <origin rpy="0 0 0" xyz="0 0 0.138"/>
    <parent link="base_link"/>
    <child link="link1"/>
    <axis xyz="0 0 1"/>
    <limit effort="100" lower="-2.70526" upper="2.70526" velocity="5"/>
  </joint>
  <link name="link2">
    <inertial>
      <origin rpy="0 0 0" xyz="0.00079686657 -0.07890325930 0.00111849422"/>
      <mass value="0.69381908"/>
      <inertia ixx="0.00201093857656" ixy="-0.00002399426785" ixz="-0.00000072824714" iyy="0.00063544232555" iyz="0.00005831284343" izz="0.00181943989593"/>
    </inertial>
    <visual>
      <origin rpy="0 0 0" xyz="0 0 0"/>
      <geometry>
        <mesh filename="package://my_robot_description/meshes/robots/nero/link2.stl"/>
      </geometry>
    </visual>
    <collision>
      <origin rpy="0 0 0" xyz="0 0 0"/>
      <geometry>
        <mesh filename="package://my_robot_description/meshes/robots/nero/link2.stl"/>
      </geometry>
    </collision>
  </link>
  <joint name="joint2" type="revolute">
    <origin rpy="1.5707963  3.1415926 0" xyz="0 0 0"/>
    <parent link="link1"/>
    <child link="link2"/>
    <axis xyz="0 0 1"/>
    <limit effort="100" lower="-1.74" upper="1.74" velocity="5"/>
  </joint>
  <link name="link3">
    <inertial>
      <origin rpy="0 0 0" xyz="0.00014513363 -0.00121378766 -0.04861136795"/>
      <mass value="0.67246544"/>
      <inertia ixx="0.00343229961910" ixy="-0.00000026976739" ixz="0.00000305078107" iyy="0.00338662526897" iyz="-0.00003550220027" izz="0.00028853579710"/>
    </inertial>
    <visual>
      <origin rpy="0 0 0" xyz="0 0 0"/>
      <geometry>
        <mesh filename="package://my_robot_description/meshes/robots/nero/link3.stl"/>
      </geometry>
    </visual>
    <collision>
      <origin rpy="0 0 0" xyz="0 0 0"/>
      <geometry>
        <mesh filename="package://my_robot_description/meshes/robots/nero/link3.stl"/>
      </geometry>
    </collision>
  </link>
  <joint name="joint3" type="revolute">
    <origin rpy="-1.5707963  0 3.1415926926" xyz="0 -0.31 0"/>
    <parent link="link2"/>
    <child link="link3"/>
    <axis xyz="0 0 1"/>
    <limit effort="100" lower="-2.75" upper="2.75" velocity="5"/>
  </joint>
  <link name="link4">
    <inertial>
      <origin rpy="0 0 0" xyz="-0.00031334623 -0.05675192422 0.00076056133"/>
      <mass value="0.48451414"/>
      <inertia ixx="0.00050386693505" ixy="-0.00000529675237" ixz="0.00000006134740" iyy="0.00023502068202" iyz="0.00001815932566" izz="0.00040149523118"/>
    </inertial>
    <visual>
      <origin rpy="0 0 0" xyz="0 0 0"/>
      <geometry>
        <mesh filename="package://my_robot_description/meshes/robots/nero/link4.stl"/>
      </geometry>
    </visual>
    <collision>
      <origin rpy="0 0 0" xyz="0 0 0"/>
      <geometry>
        <mesh filename="package://my_robot_description/meshes/robots/nero/link4.stl"/>
      </geometry>
    </collision>
  </link>
  <joint name="joint4" type="revolute">
    <origin rpy="-1.5707963  0 3.1415926926" xyz="0 0 0"/>
    <parent link="link3"/>
    <child link="link4"/>
    <axis xyz="0 0 1"/>
    <limit effort="100" lower="-1.01" upper="2.14" velocity="5"/>
  </joint>
  <link name="link5">
    <inertial>
      <origin rpy="0 0 0" xyz="0.00265591357 0.00201195753 -0.11620855434"/>
      <mass value="0.58368405"/>
      <inertia ixx="0.00089537686723" ixy="0.00000648218232" ixz="-0.00001463346849" iyy="0.00085866122972" iyz="-0.00004035185637" izz="0.00021774946532"/>
    </inertial>
    <visual>
      <origin rpy="0 0 0" xyz="0 0 0"/>
      <geometry>
        <mesh filename="package://my_robot_description/meshes/robots/nero/link5.stl"/>
      </geometry>
    </visual>
    <collision>
      <origin rpy="0 0 0" xyz="0 0 0"/>
      <geometry>
        <mesh filename="package://my_robot_description/meshes/robots/nero/link5.stl"/>
      </geometry>
    </collision>
  </link>
  <joint name="joint5" type="revolute">
    <origin rpy="1.5707963  -1.5707963  0" xyz="0 -0.27001 0"/>
    <parent link="link4"/>
    <child link="link5"/>
    <axis xyz="0 0 1"/>
    <limit effort="100" lower="-2.75" upper="2.75" velocity="5"/>
  </joint>
  <link name="link6">
    <inertial>
      <origin rpy="0 0 0" xyz="0.00009501505 0.00107831174 -0.00019110990"/>
      <mass value="0.3140406"/>
      <inertia ixx="0.00006027211661" ixy="-0.00000024650903" ixz="0.00000015701294" iyy="0.00004699514792" iyz="0.00000004170875" izz="0.00005756771792"/>
    </inertial>
    <visual>
      <origin rpy="0 0 0" xyz="0 0 0"/>
      <geometry>
        <mesh filename="package://my_robot_description/meshes/robots/nero/link6.stl"/>
      </geometry>
    </visual>
    <collision>
      <origin rpy="0 0 0" xyz="0 0 0"/>
      <geometry>
        <mesh filename="package://my_robot_description/meshes/robots/nero/link6.stl"/>
      </geometry>
    </collision>
  </link>
  <joint name="joint6" type="revolute">
    <origin rpy="1.5707963  -1.5707963  0" xyz="0 0 0"/>
    <parent link="link5"/>
    <child link="link6"/>
    <axis xyz="0 0 1"/>
    <limit effort="100" lower="-0.73" upper="0.95" velocity="5"/>
  </joint>
  <link name="link7">
    <inertial>
      <origin rpy="0 0 0" xyz="-0.00014000 -0.00010000 -0.00275000"/>
      <mass value="0.000001"/>
      <inertia ixx="1.1000000000000001e-07" ixy="0" ixz="0" iyy="1.1000000000000001e-07" iyz="0" izz="1.9999999999999999e-07"/>
    </inertial>
    <visual>
      <origin rpy="0 0 0" xyz="0 0 0"/>
      <geometry>
        <mesh filename="package://my_robot_description/meshes/robots/nero/link7.stl"/>
      </geometry>
    </visual>
    <collision>
      <origin rpy="0 0 0" xyz="0 0 0"/>
      <geometry>
        <mesh filename="package://my_robot_description/meshes/robots/nero/link7.stl"/>
      </geometry>
    </collision>
  </link>
  <joint name="joint7" type="revolute">
    <origin rpy="1.5707963 0 0" xyz="0 -0.0235 0"/>
    <parent link="link6"/>
    <child link="link7"/>
    <axis xyz="0 0 1"/>
    <limit effort="100" lower="-1.5707963" upper="1.5707963" velocity="5"/>
  </joint>
  <link name="gripper_flange">
    <inertial>
      <origin rpy="0 0 0" xyz="0.0 0.0 -0.00032"/>
      <mass value="0.04771096"/>
      <inertia ixx="2.697e-05" ixy="0" ixz="0" iyy="4.311e-05" iyz="0" izz="2.479e-05"/>
    </inertial>
    <visual>
      <origin rpy="0 0 0" xyz="0 0 0"/>
      <geometry>
        <mesh filename="package://my_robot_description/meshes/robots/nero/gripper_flange.stl"/>
      </geometry>
    </visual>
    <collision>
      <origin rpy="0 0 0" xyz="0 0 0"/>
      <geometry>
        <mesh filename="package://my_robot_description/meshes/robots/nero/gripper_flange.stl"/>
      </geometry>
    </collision>
  </link>
  <joint name="gripper_flange_joint" type="fixed">
    <origin rpy="-1.5708 0 -1.5708" xyz="0.032 0 -0.0235"/>
    <parent link="link7"/>
    <child link="gripper_flange"/>
  </joint>
  <!--
        grinder_with_camera.xacro
        =========================
        Attaches grinder with camera to nero arm flange.

        Usage:
        <xacro:include filename="$(find my_robot_description)/urdf/end_effectors/grinder/grinder_with_camera.xacro"/>
        <xacro:grinder_with_camera parent="gripper_flange"/>
    -->
  <!-- Grinder base link -->
  <link name="grinder_base_link">
    <inertial>
      <origin rpy="0 0 0" xyz="0 0 0.05"/>
      <mass value="0.5"/>
      <inertia ixx="0.001" ixy="0" ixz="0" iyy="0.001" iyz="0" izz="0.001"/>
    </inertial>
    <visual>
      <origin rpy="0 0 0" xyz="0 0 0"/>
      <geometry>
        <mesh filename="package://my_robot_description/meshes/end_effectors/grinder/grinder_with_camera.stl"/>
      </geometry>
      <material name="grey">
        <color rgba="0.5 0.5 0.5 1.0"/>
      </material>
    </visual>
    <collision>
      <origin rpy="0 0 0" xyz="0 0 0.05"/>
      <geometry>
        <mesh filename="package://my_robot_description/meshes/end_effectors/grinder/grinder_with_camera.stl"/>
      </geometry>
    </collision>
  </link>
  <!-- Joint to parent (gripper_flange) -->
  <joint name="grinder_base_joint" type="fixed">
    <origin rpy="0 0 0" xyz="0 0 0.01"/>
    <parent link="gripper_flange"/>
    <child link="grinder_base_link"/>
  </joint>
  <!-- Camera link (extracted from grinder model) -->
  <link name="grinder_camera_link">
    <inertial>
      <origin rpy="0 0 0" xyz="0 0 0"/>
      <mass value="0.1"/>
      <inertia ixx="0.0001" ixy="0" ixz="0" iyy="0.0001" iyz="0" izz="0.0001"/>
    </inertial>
    <visual>
      <origin rpy="0 0 0" xyz="0 0 0"/>
      <geometry>
        <box size="0.02 0.02 0.02"/>
      </geometry>
    </visual>
  </link>
  <!-- Camera optical frame (ROS convention) -->
  <link name="grinder_camera_optical_frame"/>
  <!-- Joint from grinder base to camera -->
  <joint name="grinder_camera_joint" type="fixed">
    <!-- Adjust these values based on your actual camera position in the model -->
    <origin rpy="-1.5708 0 -1.5708" xyz="0.105 0 0.04"/>
    <parent link="grinder_base_link"/>
    <child link="grinder_camera_link"/>
  </joint>
  <!-- Joint to optical frame -->
  <joint name="grinder_camera_optical_joint" type="fixed">
    <origin rpy="-1.5708 0 -1.5708" xyz="0 0 0"/>
    <parent link="grinder_camera_link"/>
    <child link="grinder_camera_optical_frame"/>
  </joint>
</robot>
